<?xml version="1.0" ?>
<!-- =================================================================================== -->
<!-- |    This document was autogenerated by xacro from ../robot/hand_in_world.urdf.xacro | -->
<!-- |    EDITING THIS FILE BY HAND IS NOT RECOMMENDED                                 | -->
<!-- =================================================================================== -->
<robot name="complete_soft_hand" xmlns:xacro="http://ros.org/wiki/xacro">
  <material name="LightGrey">
    <color rgba="0.7 0.7 0.7 1.0"/>
  </material>
  <material name="DarkGrey">
    <color rgba="0.4 0.4 0.4 1.0"/>
  </material>
  <material name="Black">
    <color rgba="0.0 0.0 0.0 1.0"/>
  </material>
  <material name="DarkGolden">
    <color rgba="0.4 0.4 0.3 1.0"/>
  </material>
  <material name="Blue">
    <color rgba="0.0 0.0 0.8 0.9"/>
  </material>
  <material name="LightBlue">
    <color rgba="0.0 0.4 1.0 0.5"/>
  </material>
  <link name="world">
    <!--     <visual>
      <origin xyz="0 0 0" rpy="0 0 0"/>
      <geometry>
        <box size="1 1 1.0"/>
      </geometry>
    </visual> -->
  </link>
  <joint name="hand_palm_joint" type="fixed">
    <origin rpy="0 0 0" xyz="0 0 0"/>
    <parent link="world"/>
    <child link="hand_palm_link"/>
    <!-- <axis xyz="0 1 0" /> -->
    <!-- <limit lower="${-90*pi/180}" upper="${90*pi/180}" effort="${effort}" velocity="${velocity}"/> -->
  </joint>
  <link name="hand_palm_link">
    <visual>
      <origin rpy="0 0 0" xyz="0 0 0"/>
      <geometry>
        <!-- <mesh filename="package://complete_soft_hand/meshes/palm_hand.stl" scale=" .001 .001 .001" /> -->
        <mesh filename="package://complete_soft_hand/meshes/palm_hand2.stl" scale=" .001 .001 .001"/>
      </geometry>
      <material name="LightGrey"/>
    </visual>
  </link>
  <joint name="hand_thumb_abd_joint" type="revolute">
    <origin rpy="0 0 -0.43633181" xyz="-0.0418769 0.0538740 -0.00691972 "/>
    <parent link="hand_palm_link"/>
    <child link="hand_thumb_knuckle_link"/>
    <axis xyz="0 1 0"/>
    <limit effort="100" lower="-1.57079632679" upper="0.0" velocity="100"/>
  </joint>
  <link name="hand_thumb_knuckle_link">
    <visual>
      <origin rpy="0 0 0" xyz="0 0 0"/>
      <geometry>
        <mesh filename="package://complete_soft_hand/meshes/phalanx_thumb_injection.stl" scale=" .001 .001 .001"/>
      </geometry>
      <material name="DarkGolden"/>
    </visual>
  </link>
  <joint name="hand_thumb_inner_joint " type="revolute">
    <origin rpy="-1.9974238811 0 0" xyz="-0.0225 0 -0.0033"/>
    <parent link="hand_thumb_knuckle_link"/>
    <child link="hand_thumb_inner_link  "/>
    <axis xyz="0 1 0"/>
    <limit effort="100" lower="0.0" upper="0.785398163397" velocity="100"/>
  </joint>
  <link name="hand_thumb_inner_link  "> 
		</link>
  <joint name="hand_thumb_inner_joint" type="revolute">
    <origin rpy="0 0 0" xyz="-0.013 0 0"/>
    <parent link="hand_thumb_inner_link  "/>
    <child link="hand_thumb_proximal_link"/>
    <axis xyz="0 1 0"/>
    <mimic joint="hand_thumb_inner_joint " multiplier="1"/>
    <limit effort="100" lower="0.0" upper="0.785398163397" velocity="100"/>
  </joint>
  <link name="hand_thumb_proximal_link">
    <visual>
      <origin rpy="0 0 0" xyz="0 0 0"/>
      <geometry>
        <mesh filename="package://complete_soft_hand/meshes/phalanx_short_injection.stl" scale=" .001 .001 .001"/>
      </geometry>
      <material name="DarkGolden"/>
    </visual>
  </link>
  <joint name="hand_thumb_middle_joint  " type="revolute">
    <origin rpy="0 0 0" xyz="-0.009 0 0"/>
    <parent link="hand_thumb_proximal_link"/>
    <child link="hand_thumb_fake_link2"/>
    <axis xyz="0 1 0"/>
    <limit effort="100" lower="0.0" upper="0.785398163397" velocity="100"/>
  </joint>
  <link name="hand_thumb_fake_link2"> 
		</link>
  <joint name="hand_thumb_middle_joint" type="revolute">
    <origin rpy="0 0 0" xyz="-0.013 0 0"/>
    <parent link="hand_thumb_fake_link2"/>
    <child link="hand_thumb_middle_link"/>
    <axis xyz="0 1 0"/>
    <mimic joint="hand_thumb_middle_joint  " multiplier="1"/>
    <limit effort="100" lower="0.0" upper="0.785398163397" velocity="100"/>
  </joint>
  <link name="hand_thumb_middle_link">
    <visual>
      <origin rpy="0 0 0" xyz="0 0 0"/>
      <geometry>
        <mesh filename="package://complete_soft_hand/meshes/phalanx_short_injection.stl" scale=" .001 .001 .001"/>
      </geometry>
      <material name="DarkGolden"/>
    </visual>
  </link>
  <joint name="hand_thumb_outer_joint " type="revolute">
    <origin rpy="0 0 0" xyz="-0.009 0 0.0"/>
    <parent link="hand_thumb_middle_link"/>
    <child link="hand_thumb_fake_link3"/>
    <axis xyz="0 1 0"/>
    <limit effort="100" lower="0.0" upper="0.785398163397" velocity="100"/>
  </joint>
  <link name="hand_thumb_fake_link3"> 
		</link>
  <joint name="hand_thumb_outer_joint" type="revolute">
    <origin rpy="0 0 0" xyz="-0.013 0 0"/>
    <parent link="hand_thumb_fake_link3"/>
    <child link="hand_thumb_distal_link"/>
    <axis xyz="0 1 0"/>
    <mimic joint="hand_thumb_outer_joint " multiplier="1"/>
    <limit effort="100" lower="0.0" upper="0.785398163397" velocity="100"/>
  </joint>
  <link name="hand_thumb_distal_link">
    <visual>
      <origin rpy="0 0 0" xyz="0 0 0"/>
      <geometry>
        <mesh filename="package://complete_soft_hand/meshes/phalanx_distal_out_no_ati.stl" scale=" .001 .001 .001"/>
      </geometry>
      <material name="DarkGolden"/>
    </visual>
  </link>
  <joint name="hand_index_abd_joint" type="revolute">
    <origin rpy="3.14159265359 0 -1.2217304764" xyz="-0.0285 0.0943918 0.00205"/>
    <parent link="hand_palm_link"/>
    <child link="hand_index_knuckle_link"/>
    <axis xyz="0 0 1"/>
    <limit effort="100" lower="-0.523598775598" upper="0.785398163397" velocity="100"/>
  </joint>
  <link name="hand_index_knuckle_link">
    <visual>
      <origin rpy="0 0 0" xyz="0 0 0"/>
      <geometry>
        <mesh filename="package://complete_soft_hand/meshes/phalanx_prossimal_injection.stl" scale=" .001 .001 .001"/>
      </geometry>
      <material name="DarkGolden"/>
    </visual>
  </link>
  <joint name="hand_index_inner_joint " type="revolute">
    <origin rpy="0 0 0" xyz="-0.009 0 0"/>
    <parent link="hand_index_knuckle_link"/>
    <child link="hand_index_inner_link  "/>
    <axis xyz="0 1 0"/>
    <limit effort="100" lower="0.0" upper="0.785398163397" velocity="100"/>
  </joint>
  <link name="hand_index_inner_link  "> 
		</link>
  <joint name="hand_index_inner_joint" type="revolute">
    <origin rpy="0 0 0" xyz="-0.013 0 0"/>
    <parent link="hand_index_inner_link  "/>
    <child link="hand_index_proximal_link"/>
    <axis xyz="0 1 0"/>
    <mimic joint="hand_index_inner_joint " multiplier="1"/>
    <limit effort="100" lower="0.0" upper="0.785398163397" velocity="100"/>
  </joint>
  <link name="hand_index_proximal_link">
    <visual>
      <origin rpy="0 0 0" xyz="0 0 0"/>
      <geometry>
        <mesh filename="package://complete_soft_hand/meshes/phalanx_short_injection.stl" scale=" .001 .001 .001"/>
      </geometry>
      <material name="DarkGolden"/>
    </visual>
  </link>
  <joint name="hand_index_middle_joint  " type="revolute">
    <origin rpy="0 0 0" xyz="-0.009 0 0"/>
    <parent link="hand_index_proximal_link"/>
    <child link="hand_index_fake_link2"/>
    <axis xyz="0 1 0"/>
    <limit effort="100" lower="0.0" upper="0.785398163397" velocity="100"/>
  </joint>
  <link name="hand_index_fake_link2"> 
		</link>
  <joint name="hand_index_middle_joint" type="revolute">
    <origin rpy="0 0 0" xyz="-0.013 0 0"/>
    <parent link="hand_index_fake_link2"/>
    <child link="hand_index_middle_link"/>
    <axis xyz="0 1 0"/>
    <mimic joint="hand_index_middle_joint  " multiplier="1"/>
    <limit effort="100" lower="0.0" upper="0.785398163397" velocity="100"/>
  </joint>
  <link name="hand_index_middle_link">
    <visual>
      <origin rpy="0 0 0" xyz="0 0 0"/>
      <geometry>
        <mesh filename="package://complete_soft_hand/meshes/phalanx_short_injection.stl" scale=" .001 .001 .001"/>
      </geometry>
      <material name="DarkGolden"/>
    </visual>
  </link>
  <joint name="hand_index_outer_joint " type="revolute">
    <origin rpy="0 0 0" xyz="-0.009 0 0"/>
    <parent link="hand_index_middle_link"/>
    <child link="hand_index_fake_link3"/>
    <axis xyz="0 1 0"/>
    <limit effort="100" lower="0.0" upper="0.785398163397" velocity="100"/>
  </joint>
  <link name="hand_index_fake_link3"> 
		</link>
  <joint name="hand_index_outer_joint" type="revolute">
    <origin rpy="0 0 0" xyz="-0.013 0 0"/>
    <parent link="hand_index_fake_link3"/>
    <child link="hand_index_distal_link"/>
    <axis xyz="0 1 0"/>
    <mimic joint="hand_index_outer_joint " multiplier="1"/>
    <limit effort="100" lower="0.0" upper="0.785398163397" velocity="100"/>
  </joint>
  <link name="hand_index_distal_link">
    <visual>
      <origin rpy="0 0 0" xyz="0 0 0"/>
      <geometry>
        <mesh filename="package://complete_soft_hand/meshes/phalanx_distal_out_no_ati.stl" scale=" .001 .001 .001"/>
      </geometry>
      <material name="DarkGolden"/>
    </visual>
  </link>
  <joint name="hand_middle_abd_joint" type="revolute">
    <origin rpy="3.14159265359 0 -1.57079632679" xyz="-0.009 0.107892 0.00205"/>
    <parent link="hand_palm_link"/>
    <child link="hand_middle_knuckle_link"/>
    <axis xyz="0 0 1"/>
    <limit effort="100" lower="-0.523598775598" upper="0.785398163397" velocity="100"/>
  </joint>
  <link name="hand_middle_knuckle_link">
    <visual>
      <origin rpy="0 0 0" xyz="0 0 0"/>
      <geometry>
        <mesh filename="package://complete_soft_hand/meshes/phalanx_prossimal_injection.stl" scale=" .001 .001 .001"/>
      </geometry>
      <material name="DarkGolden"/>
    </visual>
  </link>
  <joint name="hand_middle_inner_joint " type="revolute">
    <origin rpy="0 0 0" xyz="-0.009 0 0"/>
    <parent link="hand_middle_knuckle_link"/>
    <child link="hand_middle_inner_link  "/>
    <axis xyz="0 1 0"/>
    <limit effort="100" lower="0.0" upper="0.785398163397" velocity="100"/>
  </joint>
  <link name="hand_middle_inner_link  "> 
		</link>
  <joint name="hand_middle_inner_joint" type="revolute">
    <origin rpy="0 0 0" xyz="-0.013 0 0"/>
    <parent link="hand_middle_inner_link  "/>
    <child link="hand_middle_proximal_link"/>
    <axis xyz="0 1 0"/>
    <mimic joint="hand_middle_inner_joint " multiplier="1"/>
    <limit effort="100" lower="0.0" upper="0.785398163397" velocity="100"/>
  </joint>
  <link name="hand_middle_proximal_link">
    <visual>
      <origin rpy="0 0 0" xyz="0 0 0"/>
      <geometry>
        <mesh filename="package://complete_soft_hand/meshes/phalanx_short_injection.stl" scale=" .001 .001 .001"/>
      </geometry>
      <material name="DarkGolden"/>
    </visual>
  </link>
  <joint name="hand_middle_middle_joint  " type="revolute">
    <origin rpy="0 0 0" xyz="-0.009 0 0"/>
    <parent link="hand_middle_proximal_link"/>
    <child link="hand_middle_fake_link2"/>
    <axis xyz="0 1 0"/>
    <limit effort="100" lower="0.0" upper="0.785398163397" velocity="100"/>
  </joint>
  <link name="hand_middle_fake_link2"> 
		</link>
  <joint name="hand_middle_middle_joint" type="revolute">
    <origin rpy="0 0 0" xyz="-0.013 0 0"/>
    <parent link="hand_middle_fake_link2"/>
    <child link="hand_middle_middle_link"/>
    <axis xyz="0 1 0"/>
    <mimic joint="hand_middle_middle_joint  " multiplier="1"/>
    <limit effort="100" lower="0.0" upper="0.785398163397" velocity="100"/>
  </joint>
  <link name="hand_middle_middle_link">
    <visual>
      <origin rpy="0 0 0" xyz="0 0 0"/>
      <geometry>
        <mesh filename="package://complete_soft_hand/meshes/phalanx_short_injection.stl" scale=" .001 .001 .001"/>
      </geometry>
      <material name="DarkGolden"/>
    </visual>
  </link>
  <joint name="hand_middle_outer_joint " type="revolute">
    <origin rpy="0 0 0" xyz="-0.009 0 0"/>
    <parent link="hand_middle_middle_link"/>
    <child link="hand_middle_fake_link3"/>
    <axis xyz="0 1 0"/>
    <limit effort="100" lower="0.0" upper="0.785398163397" velocity="100"/>
  </joint>
  <link name="hand_middle_fake_link3"> 
		</link>
  <joint name="hand_middle_outer_joint" type="revolute">
    <origin rpy="0 0 0" xyz="-0.013 0 0"/>
    <parent link="hand_middle_fake_link3"/>
    <child link="hand_middle_distal_link"/>
    <axis xyz="0 1 0"/>
    <mimic joint="hand_middle_outer_joint " multiplier="1"/>
    <limit effort="100" lower="0.0" upper="0.785398163397" velocity="100"/>
  </joint>
  <link name="hand_middle_distal_link">
    <visual>
      <origin rpy="0 0 0" xyz="0 0 0"/>
      <geometry>
        <mesh filename="package://complete_soft_hand/meshes/phalanx_distal_out_no_ati.stl" scale=" .001 .001 .001"/>
      </geometry>
      <material name="DarkGolden"/>
    </visual>
  </link>
  <joint name="hand_ring_abd_joint" type="revolute">
    <origin rpy="3.14159265359 0 -1.74532925199" xyz="0.0105 0.0943918 0.00205"/>
    <parent link="hand_palm_link"/>
    <child link="hand_ring_knuckle_link"/>
    <axis xyz="0 0 1"/>
    <limit effort="100" lower="-0.523598775598" upper="0.785398163397" velocity="100"/>
  </joint>
  <link name="hand_ring_knuckle_link">
    <visual>
      <origin rpy="0 0 0" xyz="0 0 0"/>
      <geometry>
        <mesh filename="package://complete_soft_hand/meshes/phalanx_prossimal_injection.stl" scale=" .001 .001 .001"/>
      </geometry>
      <material name="DarkGolden"/>
    </visual>
  </link>
  <joint name="hand_ring_inner_joint " type="revolute">
    <origin rpy="0 0 0" xyz="-0.009 0 0"/>
    <parent link="hand_ring_knuckle_link"/>
    <child link="hand_ring_inner_link  "/>
    <axis xyz="0 1 0"/>
    <limit effort="100" lower="0.0" upper="0.785398163397" velocity="100"/>
  </joint>
  <link name="hand_ring_inner_link  "> 
		</link>
  <joint name="hand_ring_inner_joint" type="revolute">
    <origin rpy="0 0 0" xyz="-0.013 0 0"/>
    <parent link="hand_ring_inner_link  "/>
    <child link="hand_ring_proximal_link"/>
    <axis xyz="0 1 0"/>
    <mimic joint="hand_ring_inner_joint " multiplier="1"/>
    <limit effort="100" lower="0.0" upper="0.785398163397" velocity="100"/>
  </joint>
  <link name="hand_ring_proximal_link">
    <visual>
      <origin rpy="0 0 0" xyz="0 0 0"/>
      <geometry>
        <mesh filename="package://complete_soft_hand/meshes/phalanx_short_injection.stl" scale=" .001 .001 .001"/>
      </geometry>
      <material name="DarkGolden"/>
    </visual>
  </link>
  <joint name="hand_ring_middle_joint  " type="revolute">
    <origin rpy="0 0 0" xyz="-0.009 0 0"/>
    <parent link="hand_ring_proximal_link"/>
    <child link="hand_ring_fake_link2"/>
    <axis xyz="0 1 0"/>
    <limit effort="100" lower="0.0" upper="0.785398163397" velocity="100"/>
  </joint>
  <link name="hand_ring_fake_link2"> 
		</link>
  <joint name="hand_ring_middle_joint" type="revolute">
    <origin rpy="0 0 0" xyz="-0.013 0 0"/>
    <parent link="hand_ring_fake_link2"/>
    <child link="hand_ring_middle_link"/>
    <axis xyz="0 1 0"/>
    <mimic joint="hand_ring_middle_joint  " multiplier="1"/>
    <limit effort="100" lower="0.0" upper="0.785398163397" velocity="100"/>
  </joint>
  <link name="hand_ring_middle_link">
    <visual>
      <origin rpy="0 0 0" xyz="0 0 0"/>
      <geometry>
        <mesh filename="package://complete_soft_hand/meshes/phalanx_short_injection.stl" scale=" .001 .001 .001"/>
      </geometry>
      <material name="DarkGolden"/>
    </visual>
  </link>
  <joint name="hand_ring_outer_joint " type="revolute">
    <origin rpy="0 0 0" xyz="-0.009 0 0"/>
    <parent link="hand_ring_middle_link"/>
    <child link="hand_ring_fake_link3"/>
    <axis xyz="0 1 0"/>
    <limit effort="100" lower="0.0" upper="0.785398163397" velocity="100"/>
  </joint>
  <link name="hand_ring_fake_link3"> 
		</link>
  <joint name="hand_ring_outer_joint" type="revolute">
    <origin rpy="0 0 0" xyz="-0.013 0 0"/>
    <parent link="hand_ring_fake_link3"/>
    <child link="hand_ring_distal_link"/>
    <axis xyz="0 1 0"/>
    <mimic joint="hand_ring_outer_joint " multiplier="1"/>
    <limit effort="100" lower="0.0" upper="0.785398163397" velocity="100"/>
  </joint>
  <link name="hand_ring_distal_link">
    <visual>
      <origin rpy="0 0 0" xyz="0 0 0"/>
      <geometry>
        <mesh filename="package://complete_soft_hand/meshes/phalanx_distal_out_no_ati.stl" scale=" .001 .001 .001"/>
      </geometry>
      <material name="DarkGolden"/>
    </visual>
  </link>
  <joint name="hand_little_abd_joint" type="revolute">
    <origin rpy="3.14159265359 0 -1.91986217719" xyz="0.030 0.0808918 0.00205"/>
    <parent link="hand_palm_link"/>
    <child link="hand_little_knuckle_link"/>
    <axis xyz="0 0 1"/>
    <limit effort="100" lower="-0.523598775598" upper="0.785398163397" velocity="100"/>
  </joint>
  <link name="hand_little_knuckle_link">
    <visual>
      <origin rpy="0 0 0" xyz="0 0 0"/>
      <geometry>
        <mesh filename="package://complete_soft_hand/meshes/phalanx_prossimal_injection.stl" scale=" .001 .001 .001"/>
      </geometry>
      <material name="DarkGolden"/>
    </visual>
  </link>
  <joint name="hand_little_inner_joint " type="revolute">
    <origin rpy="0 0 0" xyz="-0.009 0 0"/>
    <parent link="hand_little_knuckle_link"/>
    <child link="hand_little_inner_link  "/>
    <axis xyz="0 1 0"/>
    <limit effort="100" lower="0.0" upper="0.785398163397" velocity="100"/>
  </joint>
  <link name="hand_little_inner_link  "> 
		</link>
  <joint name="hand_little_inner_joint" type="revolute">
    <origin rpy="0 0 0" xyz="-0.013 0 0"/>
    <parent link="hand_little_inner_link  "/>
    <child link="hand_little_proximal_link"/>
    <axis xyz="0 1 0"/>
    <mimic joint="hand_little_inner_joint " multiplier="1"/>
    <limit effort="100" lower="0.0" upper="0.785398163397" velocity="100"/>
  </joint>
  <link name="hand_little_proximal_link">
    <visual>
      <origin rpy="0 0 0" xyz="0 0 0"/>
      <geometry>
        <mesh filename="package://complete_soft_hand/meshes/phalanx_short_injection.stl" scale=" .001 .001 .001"/>
      </geometry>
      <material name="DarkGolden"/>
    </visual>
  </link>
  <joint name="hand_little_middle_joint  " type="revolute">
    <origin rpy="0 0 0" xyz="-0.009 0 0"/>
    <parent link="hand_little_proximal_link"/>
    <child link="hand_little_fake_link2"/>
    <axis xyz="0 1 0"/>
    <limit effort="100" lower="0.0" upper="0.785398163397" velocity="100"/>
  </joint>
  <link name="hand_little_fake_link2"> 
		</link>
  <joint name="hand_little_middle_joint" type="revolute">
    <origin rpy="0 0 0" xyz="-0.013 0 0"/>
    <parent link="hand_little_fake_link2"/>
    <child link="hand_little_middle_link"/>
    <axis xyz="0 1 0"/>
    <mimic joint="hand_little_middle_joint  " multiplier="1"/>
    <limit effort="100" lower="0.0" upper="0.785398163397" velocity="100"/>
  </joint>
  <link name="hand_little_middle_link">
    <visual>
      <origin rpy="0 0 0" xyz="0 0 0"/>
      <geometry>
        <mesh filename="package://complete_soft_hand/meshes/phalanx_short_injection.stl" scale=" .001 .001 .001"/>
      </geometry>
      <material name="DarkGolden"/>
    </visual>
  </link>
  <joint name="hand_little_outer_joint " type="revolute">
    <origin rpy="0 0 0" xyz="-0.009 0 0"/>
    <parent link="hand_little_middle_link"/>
    <child link="hand_little_fake_link3"/>
    <axis xyz="0 1 0"/>
    <limit effort="100" lower="0.0" upper="0.785398163397" velocity="100"/>
  </joint>
  <link name="hand_little_fake_link3"> 
		</link>
  <joint name="hand_little_outer_joint" type="revolute">
    <origin rpy="0 0 0" xyz="-0.013 0 0"/>
    <parent link="hand_little_fake_link3"/>
    <child link="hand_little_distal_link"/>
    <axis xyz="0 1 0"/>
    <mimic joint="hand_little_outer_joint " multiplier="1"/>
    <limit effort="100" lower="0.0" upper="0.785398163397" velocity="100"/>
  </joint>
  <link name="hand_little_distal_link">
    <visual>
      <origin rpy="0 0 0" xyz="0 0 0"/>
      <geometry>
        <mesh filename="package://complete_soft_hand/meshes/phalanx_distal_out_no_ati.stl" scale=" .001 .001 .001"/>
      </geometry>
      <material name="DarkGolden"/>
    </visual>
  </link>
</robot>
